tests/32_threads/sample_43.in
32
o
17 S 103 2 1049 216
31 S 105 8 1308 541
14 B 107 1 1773 133
6 S 108 8 1153 702
6 B 109 2 1686 83
7 B 111 8 1504 993
26 B 112 0 1893 171
21 S 113 4 1276 867
30 B 114 4 1693 330
8 S 115 4 1228 797
21 B 116 8 1833 722
4 S 117 7 1950 509
22 B 118 1 1701 436
2 B 119 2 1493 523
17 S 122 7 1717 13
15 S 124 1 1691 993
31 S 125 9 1095 313
25 S 126 5 1302 34
30 S 127 7 1075 42
4 C 117
25 C 126
7 S 132 0 1952 132
5 S 134 2 1249 101
30 C 127
28 B 136 4 1183 249
19 S 137 1 1346 522
13 B 138 0 1206 260
13 B 139 2 1414 84
17 C 103
25 S 141 2 1818 182
1 B 142 9 1443 276
22 C 118
24 S 145 3 1245 173
30 S 146 6 1616 209
29 B 147 8 1377 37
23 S 148 7 1448 312
21 B 149 0 1314 201
23 S 150 8 1374 644
24 S 151 7 1525 886
18 B 152 1 1519 344
25 C 141
20 S 154 2 1453 933
20 B 155 8 1463 750
29 S 157 7 1539 514
13 B 158 7 1885 1000
18 B 159 1 1604 431
7 C 132
23 C 150
17 S 162 0 1207 448
4 C 117
22 B 164 1 1434 257
25 B 165 9 1037 846
31 C 125
2 B 167 3 1758 518
2 S 168 1 1203 729
13 S 169 6 1650 207
0 B 170 1 1131 453
10 S 173 9 1823 239
24 B 174 4 1417 702
31 S 175 0 1379 863
28 B 176 2 1147 352
23 B 177 8 1512 920
30 C 146
16 S 179 3 1625 212
24 B 180 1 1654 456
24 S 181 8 1273 514
8 C 115
29 S 183 2 1868 35
10 C 173
22 S 185 4 1615 169
22 S 186 8 1551 37
17 B 187 3 1462 152
0 S 189 0 1923 150
4 B 190 6 1045 330
10 B 191 0 1029 33
18 S 192 9 1446 476
14 C 107
23 S 194 6 1614 946
1 C 142
20 C 155
0 C 189
6 C 109
21 S 199 5 1821 11
16 C 179
15 B 201 5 1904 849
22 B 202 4 1692 394
21 B 203 0 1442 723
19 S 204 7 1367 642
2 C 119
25 B 206 8 1217 881
23 C 150
31 S 208 9 1739 986
2 B 210 1 1905 688
17 B 211 1 1639 951
13 B 212 6 1936 17
22 C 186
17 C 187
26 S 215 5 1474 419
23 S 216 0 1085 970
22 S 217 0 1102 944
16 C 179
17 B 219 0 1751 129
29 C 157
8 S 221 6 1143 131
5 C 134
11 B 223 6 1232 67
20 C 155
10 S 225 4 1148 69
8 S 226 2 1443 479
15 S 227 9 1803 996
25 C 126
11 C 223
5 B 230 4 1345 670
27 B 231 7 1202 225
19 C 204
19 C 137
9 S 234 6 1680 377
7 B 235 3 1047 177
22 S 237 7 1953 667
21 C 116
5 S 239 1 1364 172
10 B 240 1 1095 969
21 S 241 2 1128 526
13 C 138
18 S 243 8 1821 388
9 C 234
2 S 245 4 1181 141
7 B 246 3 1892 433
9 B 247 3 1341 19
10 B 248 7 1264 347
28 S 249 6 1804 644
2 B 250 3 1792 326
19 S 251 1 1403 411
27 B 252 0 1986 376
28 B 253 4 1359 984
9 S 254 8 1774 557
2 C 245
31 S 256 2 1211 521
15 S 257 4 1264 178
28 B 258 9 1307 520
8 S 259 5 1362 72
16 B 260 1 1139 126
26 B 261 9 1275 321
4 S 262 1 1676 599
18 S 263 1 1038 363
14 B 264 1 1686 166
4 B 265 5 1051 597
11 B 266 2 1591 888
15 C 124
13 B 268 2 1022 936
7 B 269 0 1875 731
26 B 271 1 1701 934
14 C 264
30 S 273 7 1363 828
0 C 170
6 B 275 1 1249 545
12 B 276 9 1104 191
29 S 277 6 1984 734
23 C 216
4 S 279 6 1063 157
1 B 280 6 1829 948
24 C 174
0 C 170
11 B 283 8 1228 259
31 B 284 0 1468 777
13 C 138
27 S 286 1 1078 599
14 C 107
9 B 288 3 1837 112
5 S 289 0 1943 355
13 S 290 3 1646 999
0 C 189
17 C 187
24 B 293 6 1802 344
25 S 294 9 1916 923
16 C 179
1 S 296 6 1507 288
27 S 297 0 1305 181
1 S 298 0 1544 265
11 B 299 9 1294 148
8 S 300 8 1681 194
26 S 301 2 1944 425
27 C 297
26 S 303 4 1363 163
12 C 276
18 C 152
16 B 306 5 1287 622
11 S 307 2 1357 238
26 B 308 0 1520 754
5 C 289
24 S 310 7 1524 519
11 B 311 8 1177 627
25 S 312 3 1344 461
9 B 313 6 1319 593
13 C 290
26 C 301
8 B 316 9 1690 350
0 B 317 4 1702 375
11 S 318 3 1293 30
24 B 319 5 1711 370
28 S 320 3 1873 222
5 S 321 7 1268 71
18 S 322 3 1230 293
15 S 323 2 1544 841
23 B 324 6 1051 980
25 S 325 5 1470 619
10 B 326 8 1679 518
10 C 248
23 S 328 0 1962 736
30 S 329 2 1696 915
2 S 330 0 1025 29
3 S 331 5 1860 505
25 C 325
18 C 159
25 S 334 1 1526 503
14 S 335 8 1360 524
13 S 336 1 1747 383
16 S 337 6 1037 925
26 B 338 8 1944 382
28 S 339 6 1031 110
3 S 340 7 1027 562
20 B 341 7 1190 513
10 B 342 9 1778 528
2 B 343 1 1373 382
4 S 344 3 1482 743
0 B 345 0 1194 695
19 S 346 9 1851 887
17 S 347 6 1661 343
4 B 348 3 1809 761
20 C 155
17 B 350 7 1079 986
14 S 351 5 1457 260
6 S 352 9 1889 573
10 S 353 4 1902 856
0 B 354 7 1385 973
28 C 136
24 C 310
13 C 138
18 B 358 3 1280 932
2 B 359 0 1188 725
23 C 150
21 S 361 1 1602 489
11 C 283
18 S 363 1 1199 789
12 S 364 6 1791 670
7 C 235
20 C 154
17 S 367 0 1265 118
12 S 368 3 1995 387
31 B 369 1 1742 896
13 S 370 4 1759 406
4 B 371 2 1262 871
14 S 372 7 1540 904
11 B 373 1 1314 426
17 S 374 4 1273 498
4 S 375 9 1774 445
10 B 376 9 1171 462
20 C 155
2 S 378 5 1934 642
27 S 379 9 1076 322
16 B 380 2 1462 254
6 S 381 7 1357 719
12 C 276
20 C 154
28 B 384 8 1945 40
2 S 385 9 1636 292
9 B 386 4 1042 884
9 S 387 9 1535 542
19 C 204
20 C 154
11 C 318
1 C 280
9 B 392 8 1977 52
28 B 393 8 1678 833
20 S 394 4 1016 99
3 C 340
14 S 396 4 1131 703
4 B 397 5 1239 300
14 S 398 1 1719 45
4 B 399 8 1507 221
21 B 400 0 1507 878
12 B 401 0 1021 903
17 C 211
15 B 403 3 1364 836
18 S 404 8 1359 667
31 B 405 6 1343 998
7 C 269
20 S 407 3 1365 458
0 B 408 1 1804 222
24 B 409 0 1881 711
30 S 410 3 1077 838
11 B 411 4 1342 241
2 C 167
27 C 252
25 C 141
3 S 415 8 1623 909
1 B 416 8 1108 799
20 C 394
24 S 418 0 1928 50
9 C 288
11 C 411
30 B 421 7 1665 704
10 S 422 4 1149 863
31 S 423 2 1107 746
27 C 286
27 B 425 2 1241 649
0 C 189
8 C 316
12 B 428 5 1504 116
8 B 429 4 1747 295
18 C 404
12 S 431 6 1259 299
4 B 432 8 1363 769
26 C 271
27 S 434 3 1297 219
24 C 293
15 S 436 2 1212 689
19 C 137
23 C 324
21 S 439 8 1487 645
2 C 168
8 S 441 1 1920 973
9 S 442 3 1991 481
25 S 443 5 1532 254
1 B 444 4 1458 358
29 C 147
13 S 446 9 1245 560
17 B 447 0 1945 258
27 B 448 6 1569 432
18 S 449 0 1207 668
10 C 225
7 C 111
26 B 452 9 1427 685
30 S 453 7 1641 803
9 B 454 0 1134 52
22 S 455 4 1595 254
29 B 456 7 1327 701
20 B 457 3 1630 637
7 B 458 3 1558 499
29 C 157
12 B 460 0 1071 590
20 S 461 1 1268 78
6 S 462 8 1241 140
3 C 340
16 S 464 8 1201 896
17 S 465 6 1289 698
18 B 466 3 1517 72
29 B 467 5 1853 80
3 S 468 2 1195 399
21 B 469 3 1252 511
20 C 155
4 S 471 0 1118 309
3 S 472 7 1267 314
28 B 473 2 1553 455
27 B 474 4 1882 819
26 C 261
25 S 476 9 1844 468
6 B 477 7 1112 344
28 C 136
18 B 479 7 1270 748
31 S 480 4 1169 894
1 B 481 0 1191 758
17 B 482 8 1037 644
13 S 483 5 1032 167
12 C 460
5 C 134
3 B 486 9 1587 358
29 C 467
17 C 374
15 B 489 2 1413 399
10 B 490 8 1737 95
24 B 491 5 1163 148
29 S 492 2 1498 915
14 S 493 4 1944 478
28 S 494 0 1504 704
4 S 495 7 1798 332
30 S 496 9 1945 273
4 B 497 2 1004 834
28 B 498 3 1109 573
27 S 499 3 1378 227
17 C 374
14 S 501 6 1677 569
31 C 423
27 C 474
12 C 401
8 B 505 7 1311 257
22 S 506 3 1187 443
1 C 296
20 C 341
24 S 509 4 1780 538
24 C 145
17 C 162
18 B 512 3 1186 538
19 C 346
6 B 514 9 1114 841
23 C 328
31 C 369
25 C 325
29 C 157
16 C 179
13 B 520 1 1194 624
3 B 521 1 1198 773
22 S 522 7 1788 232
26 S 523 0 1725 505
24 B 524 6 1156 271
12 B 525 3 1843 814
26 S 526 7 1511 882
26 B 527 0 1498 192
4 C 279
17 B 529 5 1628 358
10 S 530 7 1250 736
2 B 531 2 1728 592
29 C 277
1 B 533 7 1756 199
1 C 280
30 B 535 2 1143 303
25 B 536 5 1069 316
21 C 439
9 S 538 4 1146 442
17 S 539 5 1098 78
0 C 408
12 S 541 5 1892 786
26 S 542 2 1944 992
26 C 523
0 B 544 2 1180 183
31 B 545 7 1375 755
17 C 529
1 S 547 5 1548 90
9 B 548 3 1640 851
7 B 549 9 1615 530
29 C 157
1 B 551 8 1304 409
2 S 552 5 1703 597
10 B 553 0 1867 551
28 B 554 4 1576 241
3 B 555 9 1994 32
24 S 556 3 1369 887
17 C 529
4 B 558 4 1988 926
16 C 306
21 S 560 0 1637 150
29 S 561 7 1714 370
4 C 495
3 B 563 6 1329 203
12 S 564 9 1477 522
29 S 565 8 1230 684
9 C 454
22 C 506
22 C 455
12 C 564
0 B 570 5 1719 27
6 C 275
19 B 572 1 1718 296
21 C 400
6 B 574 3 1187 491
5 C 134
10 S 576 8 1689 205
26 C 338
6 B 578 5 1429 224
9 C 313
26 S 580 8 1245 507
19 S 581 0 1114 993
11 S 582 0 1249 259
5 C 230
1 S 584 9 1644 855
12 S 585 3 1165 543
0 B 586 6 1065 17
2 B 587 7 1430 385
11 S 588 3 1029 316
20 S 589 3 1617 488
23 C 324
6 C 352
26 B 592 8 1384 564
13 S 593 7 1764 800
2 B 594 9 1009 252
8 B 595 0 1598 95
8 B 596 8 1009 876
28 S 597 3 1736 848
10 C 353
6 C 574
19 S 600 6 1200 393
4 S 601 5 1505 504
29 S 602 6 1312 599
10 B 603 7 1298 36
3 C 331
22 S 605 8 1393 836
