tests/32_threads/sample_44.in
32
o
8 B 101 6 1528 665
21 S 102 0 1078 440
23 S 103 4 1071 451
27 S 104 1 1887 739
24 B 106 4 1247 42
19 S 108 5 1437 525
30 B 109 1 1037 764
1 S 110 1 1423 125
0 S 112 3 1551 203
24 C 106
23 S 114 0 1611 711
23 S 115 2 1789 985
6 S 116 4 1306 903
10 B 117 0 1877 434
23 C 114
8 B 120 5 1972 26
7 B 121 4 1669 131
26 S 122 6 1993 484
7 S 124 1 1426 725
30 C 109
21 C 102
6 S 128 9 1808 816
15 S 129 6 1050 642
18 S 130 0 1576 783
8 S 132 5 1673 828
16 B 134 7 1907 61
1 B 135 0 1157 67
16 C 134
8 S 138 5 1041 237
10 B 139 8 1945 148
12 S 140 9 1296 369
23 B 141 0 1729 919
30 S 143 1 1039 383
28 B 144 4 1325 530
16 B 145 8 1851 216
4 B 146 7 1930 255
13 B 147 7 1397 175
20 S 148 9 1404 537
26 S 150 6 1300 420
10 C 139
14 S 152 6 1293 808
7 C 121
11 S 154 0 1407 377
15 S 155 2 1178 325
2 S 156 3 1615 924
29 S 158 1 1529 449
8 C 120
21 S 160 9 1932 731
26 S 161 7 1881 515
7 S 162 4 1084 25
3 S 163 1 1244 231
21 B 164 7 1111 84
24 B 165 3 1678 451
24 B 166 4 1228 901
14 C 152
21 C 102
11 B 169 8 1331 726
29 C 158
7 C 162
13 B 172 5 1460 782
1 S 174 0 1474 264
21 B 175 6 1587 499
2 B 176 5 1805 925
26 C 122
14 S 178 7 1343 720
24 C 165
14 B 180 3 1605 163
17 S 181 0 1090 379
12 C 140
11 C 154
8 S 184 6 1147 486
21 S 185 2 1506 572
7 B 186 6 1400 636
2 B 187 7 1152 403
29 S 188 2 1669 879
24 B 190 4 1690 699
14 S 191 4 1334 459
11 S 192 3 1007 940
7 B 193 5 1260 874
0 C 112
25 S 195 4 1626 864
1 S 196 2 1626 149
23 B 197 6 1977 805
4 C 146
10 C 139
8 S 200 7 1646 353
8 C 184
12 B 202 5 1258 703
5 B 203 4 1089 345
7 B 204 6 1674 826
5 C 203
13 C 147
22 S 207 8 1082 740
31 B 208 4 1396 30
6 B 209 5 1776 125
16 B 210 3 1825 973
25 B 211 7 1757 54
7 B 212 1 1855 895
30 S 213 4 1800 28
14 B 214 7 1088 175
24 S 215 4 1769 26
12 B 216 0 1161 851
26 B 217 0 1985 29
21 C 164
9 B 219 8 1357 613
26 S 220 0 1023 944
4 S 221 5 1855 450
5 C 203
26 C 220
3 S 224 9 1665 144
14 C 180
4 C 221
9 C 219
7 C 124
1 B 229 7 1141 172
1 S 230 7 1379 812
31 B 231 7 1189 370
21 B 232 6 1796 932
6 C 116
2 S 234 9 1422 732
21 B 235 9 1872 230
16 C 134
22 S 237 3 1654 77
31 S 238 0 1992 982
25 C 195
13 C 172
23 C 103
26 C 161
29 C 188
23 S 244 0 1366 677
18 C 130
11 B 246 8 1100 866
9 C 219
1 C 174
27 B 249 2 1422 990
9 C 219
19 C 108
26 B 252 5 1559 983
17 S 253 9 1769 131
7 B 254 9 1726 123
25 C 195
5 S 256 0 1712 878
26 S 257 4 1175 870
5 B 258 8 1598 716
26 C 220
0 C 112
18 S 261 2 1200 399
4 S 262 4 1220 689
28 S 263 9 1449 830
23 S 264 9 1517 506
24 B 265 9 1003 230
4 B 266 3 1862 381
0 B 267 0 1649 513
23 C 244
26 B 269 1 1595 797
27 C 249
8 B 271 8 1276 697
13 B 272 5 1279 666
23 B 273 1 1889 617
21 B 274 4 1823 658
24 B 275 0 1648 543
6 C 128
12 C 202
29 C 158
31 C 238
0 S 280 9 1892 347
19 S 281 4 1923 579
5 C 203
29 C 188
19 B 284 4 1410 767
16 S 285 0 1722 993
1 C 196
17 C 253
15 B 288 2 1960 18
17 C 253
17 C 181
28 B 291 0 1944 273
2 B 292 4 1513 790
9 B 293 4 1959 56
9 B 294 7 1736 553
0 C 112
25 S 296 4 1319 244
24 C 166
13 C 147
13 S 299 0 1866 538
17 C 181
14 C 178
22 C 207
28 B 303 5 1641 724
26 C 220
15 C 288
0 C 267
3 B 307 2 1062 829
31 B 308 3 1356 216
19 S 309 2 1515 978
15 B 310 4 1990 23
15 S 311 0 1122 802
24 C 190
10 S 313 5 1931 567
14 S 314 1 1278 967
20 B 315 6 1414 220
13 B 316 3 1058 335
22 C 207
6 S 318 2 1095 263
11 C 169
16 C 210
12 S 321 2 1499 546
12 S 322 4 1345 375
23 B 323 4 1920 974
31 C 208
21 B 325 4 1608 811
4 B 326 2 1461 839
22 B 327 1 1141 220
0 S 328 5 1838 283
20 S 329 1 1976 270
4 B 330 9 1948 124
26 B 331 6 1017 831
7 B 332 7 1642 420
15 B 333 0 1194 931
24 C 275
17 B 335 7 1777 806
7 C 212
17 B 337 8 1318 737
11 B 338 4 1421 469
0 C 267
16 S 340 6 1845 59
23 S 341 2 1487 262
6 B 342 4 1538 226
6 B 343 6 1842 483
5 C 256
4 B 345 6 1005 631
1 C 174
8 C 138
12 S 348 8 1134 843
11 B 349 6 1327 217
26 C 269
12 S 351 8 1593 457
11 C 192
29 B 353 9 1599 247
15 C 333
29 C 353
3 C 307
25 C 211
25 S 358 7 1418 797
27 S 359 4 1815 581
21 C 175
5 S 361 7 1766 167
18 C 261
2 S 363 1 1452 529
21 S 364 1 1846 84
5 C 258
1 C 230
12 S 367 4 1660 341
8 S 368 3 1716 92
13 B 369 7 1775 884
13 B 370 5 1251 376
13 B 371 8 1021 291
3 S 372 4 1914 764
10 S 373 5 1046 117
13 B 374 2 1459 783
6 B 375 0 1838 729
1 S 376 3 1414 73
10 C 139
13 C 316
9 C 294
25 C 211
12 S 381 3 1621 44
5 B 382 6 1508 834
7 S 383 7 1442 535
19 S 384 9 1941 765
3 C 224
8 S 386 4 1583 106
28 C 263
5 C 382
0 S 389 6 1423 960
22 C 327
8 B 391 7 1455 605
5 C 258
31 C 238
4 B 394 1 1313 206
12 B 395 1 1656 571
27 B 396 4 1533 375
12 S 397 5 1218 639
4 C 345
24 S 399 6 1640 127
3 C 307
8 C 271
7 B 402 2 1277 826
30 B 403 5 1370 390
3 B 404 2 1201 74
2 S 405 0 1690 790
22 C 237
6 C 343
11 C 154
21 S 409 6 1765 107
7 S 410 7 1980 704
26 S 411 0 1828 114
1 S 412 5 1712 237
7 S 413 2 1176 357
22 B 414 7 1490 240
2 C 363
23 S 416 3 1288 858
22 C 207
21 B 418 2 1530 561
1 B 419 8 1984 610
13 B 420 6 1557 763
4 S 421 8 1693 844
9 S 422 7 1101 50
18 B 423 1 1171 266
24 C 215
26 S 425 0 1579 123
24 C 399
31 C 231
31 C 238
5 B 429 6 1455 675
13 S 430 2 1732 712
14 B 431 9 1437 856
12 S 432 2 1880 673
7 B 433 0 1806 886
17 C 337
26 B 435 2 1620 591
12 C 367
26 C 150
5 S 438 6 1004 912
4 C 266
4 S 440 1 1946 745
12 C 140
4 C 266
17 S 443 4 1608 725
2 S 444 6 1110 270
9 S 445 5 1646 549
20 B 446 4 1099 150
10 S 447 1 1802 596
13 C 430
19 S 449 1 1018 309
28 S 450 4 1624 902
28 C 291
22 C 237
0 S 453 7 1015 189
14 C 314
9 C 219
24 S 456 2 1176 705
5 S 457 6 1532 159
3 C 307
21 B 459 2 1623 987
0 S 460 5 1051 466
28 C 450
24 C 215
18 B 463 3 1687 582
31 C 308
5 C 203
24 B 466 6 1718 734
20 C 315
13 C 370
19 B 469 8 1293 55
30 B 470 6 1201 68
20 B 471 2 1787 742
2 S 472 2 1844 21
11 C 154
31 C 238
17 C 335
18 S 476 0 1722 203
7 S 477 2 1252 60
28 C 303
26 B 479 1 1725 158
26 C 411
22 B 481 7 1207 542
24 S 482 4 1081 89
8 S 483 0 1526 706
22 B 484 8 1492 846
25 C 296
20 C 446
8 B 487 3 1830 872
10 C 117
4 B 489 9 1709 1000
9 C 445
21 B 491 0 1005 889
23 S 492 8 1363 85
14 B 493 5 1180 460
31 C 231
24 S 495 4 1749 588
22 S 496 5 1933 24
25 S 497 1 1366 596
2 C 472
5 S 499 3 1600 418
26 C 252
27 C 249
9 B 502 6 1619 376
19 B 503 4 1663 369
0 S 504 4 1432 954
23 C 115
22 C 481
25 B 507 9 1494 374
6 C 209
12 B 509 3 1456 680
23 B 510 5 1880 305
27 C 396
5 B 512 4 1915 316
15 B 513 1 1432 974
31 B 514 2 1819 863
29 S 515 5 1911 608
21 C 185
15 C 155
26 S 518 7 1660 827
9 C 294
18 C 423
30 C 403
12 S 522 9 1735 383
17 S 523 1 1047 526
17 C 253
12 S 525 3 1233 71
26 C 161
26 S 527 2 1555 574
17 B 528 7 1320 822
13 C 374
29 C 515
15 B 531 2 1658 198
27 C 396
2 C 292
16 S 534 2 1515 212
7 B 535 4 1448 456
23 B 536 3 1510 225
16 C 134
1 B 538 9 1557 551
29 C 515
14 B 540 6 1588 784
4 S 541 6 1241 493
25 S 542 7 1067 692
10 S 543 0 1625 402
27 C 396
31 B 545 2 1001 645
21 B 546 4 1885 903
29 B 547 5 1336 306
25 C 195
25 S 549 4 1576 286
3 S 550 3 1418 693
30 S 551 5 1407 200
7 S 552 0 1634 470
25 C 542
30 B 554 2 1669 99
16 C 145
21 B 556 9 1899 805
0 B 557 9 1402 613
12 B 558 2 1452 851
0 C 328
20 C 148
11 B 561 3 1140 768
9 S 562 0 1958 957
4 S 563 5 1370 461
15 S 564 6 1582 212
30 B 565 8 1552 765
26 C 257
8 C 487
6 C 342
5 C 258
3 C 404
1 C 538
19 B 572 2 1715 364
17 B 573 6 1078 705
22 S 574 4 1043 193
25 C 195
28 S 576 5 1538 173
17 B 577 7 1584 110
25 S 578 9 1652 491
11 C 561
19 S 580 7 1736 976
6 S 581 3 1380 720
5 C 429
1 S 583 0 1659 544
18 B 584 2 1034 542
14 C 191
25 S 586 2 1034 54
18 S 587 3 1746 290
25 C 549
9 S 589 9 1480 33
8 S 590 5 1751 538
8 B 591 0 1057 198
26 B 592 3 1594 962
24 S 593 8 1882 584
21 C 556
30 S 595 5 1199 668
25 S 596 8 1122 732
15 B 597 6 1797 171
25 C 195
1 B 599 9 1847 457
27 B 600 2 1670 604
24 S 601 8 1276 824
31 C 308
22 C 496
16 C 340
11 C 169
9 B 606 6 1334 446
21 S 607 4 1400 717
16 B 608 2 1812 613
0 B 609 9 1277 768
30 C 143
30 B 611 8 1080 379
12 C 397
23 S 613 4 1904 718
15 B 614 2 1051 920
4 C 221
6 C 343
5 B 617 7 1416 228
3 S 618 1 1489 953
17 S 619 4 1416 506
25 B 620 0 1363 716
4 S 621 9 1292 704
23 S 622 4 1283 161
31 S 623 4 1497 288
6 C 209
30 B 625 0 1187 434
30 B 626 9 1529 556
